<?xml version="1.0" encoding="UTF-8"?>
<testsuite name="tests.khly6517.Khly6517Tests-20210909103725" tests="1" file="tests/khly6517.py" time="7.220" timestamp="2021-09-09T10:37:45" failures="1" errors="0" skipped="0">
	<testcase classname="tests.khly6517.Khly6517Tests" name="test_that_fails" time="7.220" timestamp="2021-09-09T10:37:45" file="tests\khly6517.py" line="33">
		<failure type="AssertionError" message="PV TE:NDW1798:KHLY6517_01:FUNC does not exist"><![CDATA[Traceback (most recent call last):
  File "C:\Instrument\Apps\EPICS\support\khly6517\master\system_tests\tests\khly6517.py", line 34, in test_that_fails
    self.ca.assert_that_pv_exists("FUNC")
  File "C:\Instrument\Apps\EPICS\support\IocTestFramework\master\utils\channel_access.py", line 482, in assert_that_pv_exists
    raise AssertionError("PV {pv} does not exist".format(pv=pv))
AssertionError: PV TE:NDW1798:KHLY6517_01:FUNC does not exist
]]></failure>
	</testcase>
</testsuite>
